 * Running on http://0.0.0.0:5000/ (Press CTRL+C to quit)
making log...
 * Running on http://0.0.0.0:5000/ (Press CTRL+C to quit)
127.0.0.1 - - [29/Apr/2018 00:04:03] "POST /callback HTTP/1.1" 200 -
127.0.0.1 - - [29/Apr/2018 00:04:14] "POST /callback HTTP/1.1" 200 -
127.0.0.1 - - [29/Apr/2018 00:06:05] "POST /callback HTTP/1.1" 200 -
127.0.0.1 - - [29/Apr/2018 00:06:20] "POST /callback HTTP/1.1" 200 -
127.0.0.1 - - [29/Apr/2018 00:06:36] "POST /callback HTTP/1.1" 200 -
127.0.0.1 - - [29/Apr/2018 00:06:38] "POST /callback HTTP/1.1" 200 -
127.0.0.1 - - [29/Apr/2018 00:06:44] "POST /callback HTTP/1.1" 200 -
 * Running on http://0.0.0.0:5000/ (Press CTRL+C to quit)
127.0.0.1 - - [29/Apr/2018 00:13:15] "POST /callback HTTP/1.1" 200 -
127.0.0.1 - - [29/Apr/2018 00:13:22] "POST /callback HTTP/1.1" 200 -
127.0.0.1 - - [29/Apr/2018 00:13:29] "POST /callback HTTP/1.1" 200 -
 * Running on http://0.0.0.0:5000/ (Press CTRL+C to quit)
127.0.0.1 - - [29/Apr/2018 00:16:46] "POST /callback HTTP/1.1" 200 -
127.0.0.1 - - [29/Apr/2018 00:17:29] "POST /callback HTTP/1.1" 200 -
127.0.0.1 - - [29/Apr/2018 00:18:54] "POST /callback HTTP/1.1" 200 -
127.0.0.1 - - [29/Apr/2018 00:19:42] "POST /callback HTTP/1.1" 200 -
127.0.0.1 - - [29/Apr/2018 00:24:28] "POST /callback HTTP/1.1" 200 -
127.0.0.1 - - [29/Apr/2018 00:24:49] "POST /callback HTTP/1.1" 200 -
127.0.0.1 - - [29/Apr/2018 00:24:53] "POST /callback HTTP/1.1" 200 -
callback called
_________analyzing event_________
trying to identify user id:Ud1ec870e773a12d3ff494a8ccf348153, group_id:None
It's a solo chat room.
new solo user!
New user or room.
adding new user
Is a new indivisual
received text!
trying to identify user id:Ud1ec870e773a12d3ff494a8ccf348153, group_id:None
It's a solo chat room.
User found in room 0
2018年4月29日
利光	4月29日0時16分	こんにちは
BOT	4月29日0時16分	渋谷メンズ１０９の地下のプロントより発信しています

making log...
callback called
_________analyzing event_________
trying to identify user id:Ud1ec870e773a12d3ff494a8ccf348153, group_id:None
It's a solo chat room.
User found in room 0
received text!
trying to identify user id:Ud1ec870e773a12d3ff494a8ccf348153, group_id:None
It's a solo chat room.
User found in room 0
2018年4月29日
利光	4月29日0時16分	こんにちは
BOT	4月29日0時16分	渋谷メンズ１０９の地下のプロントより発信しています
利光	4月29日0時17分	聞こえてるか？
BOT	4月29日0時17分	渋谷メンズ１０９の地下のプロントより発信しています

making log...
callback called
_________analyzing event_________
trying to identify user id:Ud1ec870e773a12d3ff494a8ccf348153, group_id:C577cbbe2c112f8c49ff1626395ac33a9
It's a group chat room.
New room!
New user or room.
adding new user
Is a new room or new user in old room
Is a new room!
received text!
trying to identify user id:Ud1ec870e773a12d3ff494a8ccf348153, group_id:C577cbbe2c112f8c49ff1626395ac33a9
It's a group chat room.
Identified the room. Now checking if                                     the user has already spoken in that room
User found in room 1
2018年4月29日
利光	4月29日0時18分	グーグルドライブとの謎連携、できたwww
BOT	4月29日0時18分	就活大変！

making log...
callback called
_________analyzing event_________
trying to identify user id:Ud1ec870e773a12d3ff494a8ccf348153, group_id:C577cbbe2c112f8c49ff1626395ac33a9
It's a group chat room.
Identified the room. Now checking if                                     the user has already spoken in that room
User found in room 1
received text!
trying to identify user id:Ud1ec870e773a12d3ff494a8ccf348153, group_id:C577cbbe2c112f8c49ff1626395ac33a9
It's a group chat room.
Identified the room. Now checking if                                     the user has already spoken in that room
User found in room 1
2018年4月29日
利光	4月29日0時18分	グーグルドライブとの謎連携、できたwww
BOT	4月29日0時18分	就活大変！
利光	4月29日0時19分	チャットボットのフォルダにlightning-salt入れたけど、そのさらに中のlogフォルダの中に、ほぼリアルタイムに更新されてくはず。
BOT	4月29日0時19分	チャットボットのフォルダにlightning-salt入れたけど、そのさらに中のlogフォルダの中に、ほぼリアルタイムに更新されてくはず。

making log...
callback called
_________analyzing event_________
trying to identify user id:U115725037a2ad854f8505976c4c44dda, group_id:C577cbbe2c112f8c49ff1626395ac33a9
It's a group chat room.
Identified the room. Now checking if                                     the user has already spoken in that room
New user in old room!
New user or room.
adding new user
Is a new room or new user in old room
new user in old room!
received text!
trying to identify user id:U115725037a2ad854f8505976c4c44dda, group_id:C577cbbe2c112f8c49ff1626395ac33a9
It's a group chat room.
Identified the room. Now checking if                                     the user has already spoken in that room
User found in room 1
2018年4月29日
利光	4月29日0時18分	グーグルドライブとの謎連携、できたwww
BOT	4月29日0時18分	就活大変！
利光	4月29日0時19分	チャットボットのフォルダにlightning-salt入れたけど、そのさらに中のlogフォルダの中に、ほぼリアルタイムに更新されてくはず。
BOT	4月29日0時19分	チャットボットのフォルダにlightning-salt入れたけど、そのさらに中のlogフォルダの中に、ほぼリアルタイムに更新されてくはず。
しおぴー	4月29日0時24分	後で見てみます！
BOT	4月29日0時24分	後で見てみます！

making log...
callback called
_________analyzing event_________
trying to identify user id:Ud1ec870e773a12d3ff494a8ccf348153, group_id:C577cbbe2c112f8c49ff1626395ac33a9
It's a group chat room.
Identified the room. Now checking if                                     the user has already spoken in that room
User found in room 1
received text!
trying to identify user id:Ud1ec870e773a12d3ff494a8ccf348153, group_id:C577cbbe2c112f8c49ff1626395ac33a9
It's a group chat room.
Identified the room. Now checking if                                     the user has already spoken in that room
User found in room 1
2018年4月29日
利光	4月29日0時18分	グーグルドライブとの謎連携、できたwww
BOT	4月29日0時18分	就活大変！
利光	4月29日0時19分	チャットボットのフォルダにlightning-salt入れたけど、そのさらに中のlogフォルダの中に、ほぼリアルタイムに更新されてくはず。
BOT	4月29日0時19分	チャットボットのフォルダにlightning-salt入れたけど、そのさらに中のlogフォルダの中に、ほぼリアルタイムに更新されてくはず。
しおぴー	4月29日0時24分	後で見てみます！
BOT	4月29日0時24分	後で見てみます！
利光	4月29日0時24分	是非是非、二人とも！
BOT	4月29日0時24分	利光はイケメン

making log...
callback called
_________analyzing event_________
trying to identify user id:Ud1ec870e773a12d3ff494a8ccf348153, group_id:C577cbbe2c112f8c49ff1626395ac33a9
It's a group chat room.
Identified the room. Now checking if                                     the user has already spoken in that room
User found in room 1
received text!
trying to identify user id:Ud1ec870e773a12d3ff494a8ccf348153, group_id:C577cbbe2c112f8c49ff1626395ac33a9
It's a group chat room.
Identified the room. Now checking if                                     the user has already spoken in that room
User found in room 1
2018年4月29日
利光	4月29日0時18分	グーグルドライブとの謎連携、できたwww
BOT	4月29日0時18分	就活大変！
利光	4月29日0時19分	チャットボットのフォルダにlightning-salt入れたけど、そのさらに中のlogフォルダの中に、ほぼリアルタイムに更新されてくはず。
BOT	4月29日0時19分	チャットボットのフォルダにlightning-salt入れたけど、そのさらに中のlogフォルダの中に、ほぼリアルタイムに更新されてくはず。
しおぴー	4月29日0時24分	後で見てみます！
BOT	4月29日0時24分	後で見てみます！
利光	4月29日0時24分	是非是非、二人とも！
BOT	4月29日0時24分	利光はイケメン
利光	4月29日0時24分	いえい
BOT	4月29日0時24分	いえい

making log...
callback called
_________analyzing event_________
trying to identify user id:Ud1ec870e773a12d3ff494a8ccf348153, group_id:C577cbbe2c112f8c49ff1626395ac33a9
It's a group chat room.
Identified the room. Now checking if                                     the user has already spoken in that room
User found in room 1
received text!
trying to identify user id:Ud1ec870e773a12d3ff494a8ccf348153, group_id:C577cbbe2c112f8c49ff1626395ac33a9
It's a group chat room.
Identified the room. Now checking if                                     the user has already spoken in that room
User found in room 1
2018年4月29日
利光	4月29日0時18分	グーグルドライブとの謎連携、できたwww
BOT	4月29日0時18分	就活大変！
利光	4月29日0時19分	チャットボットのフォルダにlightning-salt入れたけど、そのさらに中のlogフォルダの中に、ほぼリアルタイムに更新されてくはず。
BOT	4月29日0時19分	チャットボットのフォルダにlightning-salt入れたけど、そのさらに中のlogフォルダの中に、ほぼリアルタイムに更新されてくはず。
しおぴー	4月29日0時24分	後で見てみます！
BOT	4月29日0時24分	後で見てみます！
利光	4月29日0時24分	是非是非、二人とも！
BOT	4月29日0時24分	利光はイケメン
利光	4月29日0時24分	いえい
BOT	4月29日0時24分	いえい
利光	4月29日0時25分	次のアップデートでこのフレーズ消すわww
BOT	4月29日0時25分	チャットボットのフォルダにlightning-salt入れたけど、そのさらに中のlogフォルダの中に、ほぼリアルタイムに更新されてくはず。
127.0.0.1 - - [29/Apr/2018 00:25:04] "POST /callback HTTP/1.1" 200 -
127.0.0.1 - - [29/Apr/2018 01:01:25] "POST /callback HTTP/1.1" 200 -
127.0.0.1 - - [29/Apr/2018 01:01:34] "POST /callback HTTP/1.1" 200 -
127.0.0.1 - - [29/Apr/2018 01:19:47] "POST /callback HTTP/1.1" 200 -

making log...
callback called
_________analyzing event_________
trying to identify user id:Ud1ec870e773a12d3ff494a8ccf348153, group_id:C577cbbe2c112f8c49ff1626395ac33a9
It's a group chat room.
Identified the room. Now checking if                                     the user has already spoken in that room
User found in room 1
received text!
trying to identify user id:Ud1ec870e773a12d3ff494a8ccf348153, group_id:C577cbbe2c112f8c49ff1626395ac33a9
It's a group chat room.
Identified the room. Now checking if                                     the user has already spoken in that room
User found in room 1
2018年4月29日
利光	4月29日0時18分	グーグルドライブとの謎連携、できたwww
BOT	4月29日0時18分	就活大変！
利光	4月29日0時19分	チャットボットのフォルダにlightning-salt入れたけど、そのさらに中のlogフォルダの中に、ほぼリアルタイムに更新されてくはず。
BOT	4月29日0時19分	チャットボットのフォルダにlightning-salt入れたけど、そのさらに中のlogフォルダの中に、ほぼリアルタイムに更新されてくはず。
しおぴー	4月29日0時24分	後で見てみます！
BOT	4月29日0時24分	後で見てみます！
利光	4月29日0時24分	是非是非、二人とも！
BOT	4月29日0時24分	利光はイケメン
利光	4月29日0時24分	いえい
BOT	4月29日0時24分	いえい
利光	4月29日0時25分	次のアップデートでこのフレーズ消すわww
BOT	4月29日0時25分	チャットボットのフォルダにlightning-salt入れたけど、そのさらに中のlogフォルダの中に、ほぼリアルタイムに更新されてくはず。
利光	4月29日1時1分	こいつをLINEに追加した時に、「もちろんメッセージは全部見れてるからね」みたいな一言があった方がいいと思うんだけど、「制作者が見ることができます」みたいに言わせるのは、苟も知能を持っていると見せかけているボットとしては興ざめな気がするんだよね…
BOT	4月29日1時1分	わからんねえ

making log...
callback called
_________analyzing event_________
trying to identify user id:Ud1ec870e773a12d3ff494a8ccf348153, group_id:C577cbbe2c112f8c49ff1626395ac33a9
It's a group chat room.
Identified the room. Now checking if                                     the user has already spoken in that room
User found in room 1
received text!
trying to identify user id:Ud1ec870e773a12d3ff494a8ccf348153, group_id:C577cbbe2c112f8c49ff1626395ac33a9
It's a group chat room.
Identified the room. Now checking if                                     the user has already spoken in that room
User found in room 1
2018年4月29日
利光	4月29日0時18分	グーグルドライブとの謎連携、できたwww
BOT	4月29日0時18分	就活大変！
利光	4月29日0時19分	チャットボットのフォルダにlightning-salt入れたけど、そのさらに中のlogフォルダの中に、ほぼリアルタイムに更新されてくはず。
BOT	4月29日0時19分	チャットボットのフォルダにlightning-salt入れたけど、そのさらに中のlogフォルダの中に、ほぼリアルタイムに更新されてくはず。
しおぴー	4月29日0時24分	後で見てみます！
BOT	4月29日0時24分	後で見てみます！
利光	4月29日0時24分	是非是非、二人とも！
BOT	4月29日0時24分	利光はイケメン
利光	4月29日0時24分	いえい
BOT	4月29日0時24分	いえい
利光	4月29日0時25分	次のアップデートでこのフレーズ消すわww
BOT	4月29日0時25分	チャットボットのフォルダにlightning-salt入れたけど、そのさらに中のlogフォルダの中に、ほぼリアルタイムに更新されてくはず。
利光	4月29日1時1分	こいつをLINEに追加した時に、「もちろんメッセージは全部見れてるからね」みたいな一言があった方がいいと思うんだけど、「制作者が見ることができます」みたいに言わせるのは、苟も知能を持っていると見せかけているボットとしては興ざめな気がするんだよね…
BOT	4月29日1時1分	わからんねえ
利光	4月29日1時1分	どうしたもんか
BOT	4月29日1時1分	どうしたもんか

making log...
callback called
_________analyzing event_________
trying to identify user id:U115725037a2ad854f8505976c4c44dda, group_id:C577cbbe2c112f8c49ff1626395ac33a9
It's a group chat room.
Identified the room. Now checking if                                     the user has already spoken in that room
User found in room 1
received text!
trying to identify user id:U115725037a2ad854f8505976c4c44dda, group_id:C577cbbe2c112f8c49ff1626395ac33a9
It's a group chat room.
Identified the room. Now checking if                                     the user has already spoken in that room
User found in room 1
2018年4月29日
利光	4月29日0時18分	グーグルドライブとの謎連携、できたwww
BOT	4月29日0時18分	就活大変！
利光	4月29日0時19分	チャットボットのフォルダにlightning-salt入れたけど、そのさらに中のlogフォルダの中に、ほぼリアルタイムに更新されてくはず。
BOT	4月29日0時19分	チャットボットのフォルダにlightning-salt入れたけど、そのさらに中のlogフォルダの中に、ほぼリアルタイムに更新されてくはず。
しおぴー	4月29日0時24分	後で見てみます！
BOT	4月29日0時24分	後で見てみます！
利光	4月29日0時24分	是非是非、二人とも！
BOT	4月29日0時24分	利光はイケメン
利光	4月29日0時24分	いえい
BOT	4月29日0時24分	いえい
利光	4月29日0時25分	次のアップデートでこのフレーズ消すわww
BOT	4月29日0時25分	チャットボットのフォルダにlightning-salt入れたけど、そのさらに中のlogフォルダの中に、ほぼリアルタイムに更新されてくはず。
利光	4月29日1時1分	こいつをLINEに追加した時に、「もちろんメッセージは全部見れてるからね」みたいな一言があった方がいいと思うんだけど、「制作者が見ることができます」みたいに言わせるのは、苟も知能を持っていると見せかけているボットとしては興ざめな気がするんだよね…
BOT	4月29日1時1分	わからんねえ
利光	4月29日1時1分	どうしたもんか
BOT	4月29日1時1分	どうしたもんか
しおぴー	4月29日1時19分	ログを取ってサービス向上に使用します
BOT	4月29日1時19分	今どこにいるの？

making log...
callback called
_________analyzing event_________
trying to identify user id:U115725037a2ad854f8505976c4c44dda, group_id:C577cbbe2c112f8c49ff1626395ac33a9
It's a group chat room.
Identified the room. Now checking if                                     the user has already spoken in that room
User found in room 1
received text!
trying to identify user id:U115725037a2ad854f8505976c4c44dda, group_id:C577cbbe2c112f8c49ff1626395ac33a9
It's a group chat room.
Identified the room. Now checking if                                     the user has already spoken in that room
User found in room 1
2018年4月29日
利光	4月29日0時18分	グーグルドライブとの謎連携、できたwww
BOT	4月29日0時18分	就活大変！
利光	4月29日0時19分	チャットボットのフォルダにlightning-salt入れたけど、そのさらに中のlogフォルダの中に、ほぼリアルタイムに更新されてくはず。
BOT	4月29日0時19分	チャットボットのフォルダにlightning-salt入れたけど、そのさらに中のlogフォルダの中に、ほぼリアルタイムに更新されてくはず。
しおぴー	4月29日0時24分	後で見てみます！
BOT	4月29日0時24分	後で見てみます！
利光	4月29日0時24分	是非是非、二人とも！
BOT	4月29日0時24分	利光はイケメン
利光	4月29日0時24分	いえい
BOT	4月29日0時24分	いえい
利光	4月29日0時25分	次のアップデートでこのフレーズ消すわww
BOT	4月29日0時25分	チャットボットのフォルダにlightning-salt入れたけど、そのさらに中のlogフォルダの中に、ほぼリアルタイムに更新されてくはず。
利光	4月29日1時1分	こいつをLINEに追加した時に、「もちろんメッセージは全部見れてるからね」みたいな一言があった方がいいと思うんだけど、「制作者が見ることができます」みたいに言わせるのは、苟も知能を持っていると見せかけているボットとしては興ざめな気がするんだよね…
BOT	4月29日1時1分	わからんねえ
利光	4月29日1時1分	どうしたもんか
BOT	4月29日1時1分	どうしたもんか
しおぴー	4月29日1時19分	ログを取ってサービス向上に使用します
BOT	4月29日1時19分	今どこにいるの？
しおぴー	4月29日1時19分	的なやつにするとか、、、
BOT	4月29日1時19分	グーグルドライブとの謎連携、できたwww
127.0.0.1 - - [29/Apr/2018 01:19:58] "POST /callback HTTP/1.1" 200 -
127.0.0.1 - - [29/Apr/2018 01:40:58] "POST /callback HTTP/1.1" 200 -
127.0.0.1 - - [29/Apr/2018 01:41:06] "POST /callback HTTP/1.1" 200 -
127.0.0.1 - - [29/Apr/2018 01:41:10] "POST /callback HTTP/1.1" 200 -

making log...
callback called
_________analyzing event_________
trying to identify user id:U115725037a2ad854f8505976c4c44dda, group_id:C577cbbe2c112f8c49ff1626395ac33a9
It's a group chat room.
Identified the room. Now checking if                                     the user has already spoken in that room
User found in room 1
received text!
trying to identify user id:U115725037a2ad854f8505976c4c44dda, group_id:C577cbbe2c112f8c49ff1626395ac33a9
It's a group chat room.
Identified the room. Now checking if                                     the user has already spoken in that room
User found in room 1
2018年4月29日
利光	4月29日0時18分	グーグルドライブとの謎連携、できたwww
BOT	4月29日0時18分	就活大変！
利光	4月29日0時19分	チャットボットのフォルダにlightning-salt入れたけど、そのさらに中のlogフォルダの中に、ほぼリアルタイムに更新されてくはず。
BOT	4月29日0時19分	チャットボットのフォルダにlightning-salt入れたけど、そのさらに中のlogフォルダの中に、ほぼリアルタイムに更新されてくはず。
しおぴー	4月29日0時24分	後で見てみます！
BOT	4月29日0時24分	後で見てみます！
利光	4月29日0時24分	是非是非、二人とも！
BOT	4月29日0時24分	利光はイケメン
利光	4月29日0時24分	いえい
BOT	4月29日0時24分	いえい
利光	4月29日0時25分	次のアップデートでこのフレーズ消すわww
BOT	4月29日0時25分	チャットボットのフォルダにlightning-salt入れたけど、そのさらに中のlogフォルダの中に、ほぼリアルタイムに更新されてくはず。
利光	4月29日1時1分	こいつをLINEに追加した時に、「もちろんメッセージは全部見れてるからね」みたいな一言があった方がいいと思うんだけど、「制作者が見ることができます」みたいに言わせるのは、苟も知能を持っていると見せかけているボットとしては興ざめな気がするんだよね…
BOT	4月29日1時1分	わからんねえ
利光	4月29日1時1分	どうしたもんか
BOT	4月29日1時1分	どうしたもんか
しおぴー	4月29日1時19分	ログを取ってサービス向上に使用します
BOT	4月29日1時19分	今どこにいるの？
しおぴー	4月29日1時19分	的なやつにするとか、、、
BOT	4月29日1時19分	グーグルドライブとの謎連携、できたwww
しおぴー	4月29日1時40分	仕事おわんねえ
BOT	4月29日1時40分	どうしたもんか

making log...
callback called
_________analyzing event_________
trying to identify user id:U115725037a2ad854f8505976c4c44dda, group_id:C577cbbe2c112f8c49ff1626395ac33a9
It's a group chat room.
Identified the room. Now checking if                                     the user has already spoken in that room
User found in room 1
received text!
trying to identify user id:U115725037a2ad854f8505976c4c44dda, group_id:C577cbbe2c112f8c49ff1626395ac33a9
It's a group chat room.
Identified the room. Now checking if                                     the user has already spoken in that room
User found in room 1
2018年4月29日
利光	4月29日0時18分	グーグルドライブとの謎連携、できたwww
BOT	4月29日0時18分	就活大変！
利光	4月29日0時19分	チャットボットのフォルダにlightning-salt入れたけど、そのさらに中のlogフォルダの中に、ほぼリアルタイムに更新されてくはず。
BOT	4月29日0時19分	チャットボットのフォルダにlightning-salt入れたけど、そのさらに中のlogフォルダの中に、ほぼリアルタイムに更新されてくはず。
しおぴー	4月29日0時24分	後で見てみます！
BOT	4月29日0時24分	後で見てみます！
利光	4月29日0時24分	是非是非、二人とも！
BOT	4月29日0時24分	利光はイケメン
利光	4月29日0時24分	いえい
BOT	4月29日0時24分	いえい
利光	4月29日0時25分	次のアップデートでこのフレーズ消すわww
BOT	4月29日0時25分	チャットボットのフォルダにlightning-salt入れたけど、そのさらに中のlogフォルダの中に、ほぼリアルタイムに更新されてくはず。
利光	4月29日1時1分	こいつをLINEに追加した時に、「もちろんメッセージは全部見れてるからね」みたいな一言があった方がいいと思うんだけど、「制作者が見ることができます」みたいに言わせるのは、苟も知能を持っていると見せかけているボットとしては興ざめな気がするんだよね…
BOT	4月29日1時1分	わからんねえ
利光	4月29日1時1分	どうしたもんか
BOT	4月29日1時1分	どうしたもんか
しおぴー	4月29日1時19分	ログを取ってサービス向上に使用します
BOT	4月29日1時19分	今どこにいるの？
しおぴー	4月29日1時19分	的なやつにするとか、、、
BOT	4月29日1時19分	グーグルドライブとの謎連携、できたwww
しおぴー	4月29日1時40分	仕事おわんねえ
BOT	4月29日1時40分	どうしたもんか
しおぴー	4月29日1時41分	まったくだよお
BOT	4月29日1時41分	あっそう（昭和天 皇風に）

making log...
callback called
_________analyzing event_________
trying to identify user id:U115725037a2ad854f8505976c4c44dda, group_id:C577cbbe2c112f8c49ff1626395ac33a9
It's a group chat room.
Identified the room. Now checking if                                     the user has already spoken in that room
User found in room 1
received text!
trying to identify user id:U115725037a2ad854f8505976c4c44dda, group_id:C577cbbe2c112f8c49ff1626395ac33a9
It's a group chat room.
Identified the room. Now checking if                                     the user has already spoken in that room
User found in room 1
2018年4月29日
利光	4月29日0時18分	グーグルドライブとの謎連携、できたwww
BOT	4月29日0時18分	就活大変！
利光	4月29日0時19分	チャットボットのフォルダにlightning-salt入れたけど、そのさらに中のlogフォルダの中に、ほぼリアルタイムに更新されてくはず。
BOT	4月29日0時19分	チャットボットのフォルダにlightning-salt入れたけど、そのさらに中のlogフォルダの中に、ほぼリアルタイムに更新されてくはず。
しおぴー	4月29日0時24分	後で見てみます！
BOT	4月29日0時24分	後で見てみます！
利光	4月29日0時24分	是非是非、二人とも！
BOT	4月29日0時24分	利光はイケメン
利光	4月29日0時24分	いえい
BOT	4月29日0時24分	いえい
利光	4月29日0時25分	次のアップデートでこのフレーズ消すわww
BOT	4月29日0時25分	チャットボットのフォルダにlightning-salt入れたけど、そのさらに中のlogフォルダの中に、ほぼリアルタイムに更新されてくはず。
利光	4月29日1時1分	こいつをLINEに追加した時に、「もちろんメッセージは全部見れてるからね」みたいな一言があった方がいいと思うんだけど、「制作者が見ることができます」みたいに言わせるのは、苟も知能を持っていると見せかけているボットとしては興ざめな気がするんだよね…
BOT	4月29日1時1分	わからんねえ
利光	4月29日1時1分	どうしたもんか
BOT	4月29日1時1分	どうしたもんか
しおぴー	4月29日1時19分	ログを取ってサービス向上に使用します
BOT	4月29日1時19分	今どこにいるの？
しおぴー	4月29日1時19分	的なやつにするとか、、、
BOT	4月29日1時19分	グーグルドライブとの謎連携、できたwww
しおぴー	4月29日1時40分	仕事おわんねえ
BOT	4月29日1時40分	どうしたもんか
しおぴー	4月29日1時41分	まったくだよお
BOT	4月29日1時41分	あっそう（昭和天 皇風に）
しおぴー	4月29日1時41分	手伝ってくれえ
BOT	4月29日1時41分	的なやつにするとか、、、

making log...
callback called
_________analyzing event_________127.0.0.1 - - [29/Apr/2018 01:46:02] "POST /callback HTTP/1.1" 200 -
127.0.0.1 - - [29/Apr/2018 01:46:41] "POST /callback HTTP/1.1" 200 -

trying to identify user id:Ud1ec870e773a12d3ff494a8ccf348153, group_id:C577cbbe2c112f8c49ff1626395ac33a9
It's a group chat room.
Identified the room. Now checking if                                     the user has already spoken in that room
User found in room 1
received text!
trying to identify user id:Ud1ec870e773a12d3ff494a8ccf348153, group_id:C577cbbe2c112f8c49ff1626395ac33a9
It's a group chat room.
Identified the room. Now checking if                                     the user has already spoken in that room
User found in room 1
2018年4月29日
利光	4月29日0時18分	グーグルドライブとの謎連携、できたwww
BOT	4月29日0時18分	就活大変！
利光	4月29日0時19分	チャットボットのフォルダにlightning-salt入れたけど、そのさらに中のlogフォルダの中に、ほぼリアルタイムに更新されてくはず。
BOT	4月29日0時19分	チャットボットのフォルダにlightning-salt入れたけど、そのさらに中のlogフォルダの中に、ほぼリアルタイムに更新されてくはず。
しおぴー	4月29日0時24分	後で見てみます！
BOT	4月29日0時24分	後で見てみます！
利光	4月29日0時24分	是非是非、二人とも！
BOT	4月29日0時24分	利光はイケメン
利光	4月29日0時24分	いえい
BOT	4月29日0時24分	いえい
利光	4月29日0時25分	次のアップデートでこのフレーズ消すわww
BOT	4月29日0時25分	チャットボットのフォルダにlightning-salt入れたけど、そのさらに中のlogフォルダの中に、ほぼリアルタイムに更新されてくはず。
利光	4月29日1時1分	こいつをLINEに追加した時に、「もちろんメッセージは全部見れてるからね」みたいな一言があった方がいいと思うんだけど、「制作者が見ることができます」みたいに言わせるのは、苟も知能を持っていると見せかけているボットとしては興ざめな気がするんだよね…
BOT	4月29日1時1分	わからんねえ
利光	4月29日1時1分	どうしたもんか
BOT	4月29日1時1分	どうしたもんか
しおぴー	4月29日1時19分	ログを取ってサービス向上に使用します
BOT	4月29日1時19分	今どこにいるの？
しおぴー	4月29日1時19分	的なやつにするとか、、、
BOT	4月29日1時19分	グーグルドライブとの謎連携、できたwww
しおぴー	4月29日1時40分	仕事おわんねえ
BOT	4月29日1時40分	どうしたもんか
しおぴー	4月29日1時41分	まったくだよお
BOT	4月29日1時41分	あっそう（昭和天 皇風に）
しおぴー	4月29日1時41分	手伝ってくれえ
BOT	4月29日1時41分	的なやつにするとか、、、
利光	4月29日1時46分	確かに
BOT	4月29日1時46分	いえい

making log...
callback called
_________analyzing event_________
trying to identify user id:Ud1ec870e773a12d3ff494a8ccf348153, group_id:C577cbbe2c112f8c49ff1626395ac33a9
It's a group chat room.
Identified the room. Now checking if                                     the user has already spoken in that room
User found in room 1
received text!
trying to identify user id:Ud1ec870e773a12d3ff494a8ccf348153, group_id:C577cbbe2c112f8c49ff1626395ac33a9
It's a group chat room.
Identified the room. Now checking if                                     the user has already spoken in that room
User found in room 1
2018年4月29日
利光	4月29日0時18分	グーグルドライブとの謎連携、できたwww
BOT	4月29日0時18分	就活大変！
利光	4月29日0時19分	チャットボットのフォルダにlightning-salt入れたけど、そのさらに中のlogフォルダの中に、ほぼリアルタイムに更新されてくはず。
BOT	4月29日0時19分	チャットボットのフォルダにlightning-salt入れたけど、そのさらに中のlogフォルダの中に、ほぼリアルタイムに更新されてくはず。
しおぴー	4月29日0時24分	後で見てみます！
BOT	4月29日0時24分	後で見てみます！
利光	4月29日0時24分	是非是非、二人とも！
BOT	4月29日0時24分	利光はイケメン
利光	4月29日0時24分	いえい
BOT	4月29日0時24分	いえい
利光	4月29日0時25分	次のアップデートでこのフレーズ消すわww
BOT	4月29日0時25分	チャットボットのフォルダにlightning-salt入れたけど、そのさらに中のlogフォルダの中に、ほぼリアルタイムに更新されてくはず。
利光	4月29日1時1分	こいつをLINEに追加した時に、「もちろんメッセージは全部見れてるからね」みたいな一言があった方がいいと思うんだけど、「制作者が見ることができます」みたいに言わせるのは、苟も知能を持っていると見せかけているボットとしては興ざめな気がするんだよね…
BOT	4月29日1時1分	わからんねえ
利光	4月29日1時1分	どうしたもんか
BOT	4月29日1時1分	どうしたもんか
しおぴー	4月29日1時19分	ログを取ってサービス向上に使用します
BOT	4月29日1時19分	今どこにいるの？
しおぴー	4月29日1時19分	的なやつにするとか、、、
BOT	4月29日1時19分	グーグルドライブとの謎連携、できたwww
しおぴー	4月29日1時40分	仕事おわんねえ
BOT	4月29日1時40分	どうしたもんか
しおぴー	4月29日1時41分	まったくだよお
BOT	4月29日1時41分	あっそう（昭和天 皇風に）
しおぴー	4月29日1時41分	手伝ってくれえ
BOT	4月29日1時41分	的なやつにするとか、、、
利光	4月29日1時46分	確かに
BOT	4月29日1時46分	いえい
利光	4月29日1時46分	「サービス」っていうと会社がやってるみたいで、それもまた興ざめになるから「能力」にするとか
BOT	4月29日1時46分	まったくだよお

making log...
callback called
_________analyzing event_________
trying to identify user id:Ud1ec870e773a12d3ff494a8ccf348153, group_id:C577cbbe2c112f8c49ff1626395ac33a9
It's a group chat room.
Identified the room. Now checking if                                     the user has already spoken in that room
User found in room 1
received text!
trying to identify user id:Ud1ec870e773a12d3ff494a8ccf348153, group_id:C577cbbe2c112f8c49ff1626395ac33a9
It's a group chat room.
Identified the room. Now checking if                                     the user has already spoken in that room
User found in room 1
2018年4月29日
利光	4月29日0時18分	グーグルドライブとの謎連携、できたwww
BOT	4月29日0時18分	就活大変！
利光	4月29日0時19分	チャットボットのフォルダにlightning-salt入れたけど、そのさらに中のlogフォルダの中に、ほぼリアルタイムに更新されてくはず。
BOT	4月29日0時19分	チャットボットのフォルダにlightning-salt入れたけど、そのさらに中のlogフォルダの中に、ほぼリアルタイムに更新されてくはず。
しおぴー	4月29日0時24分	後で見てみます！
BOT	4月29日0時24分	後で見てみます！
利光	4月29日0時24分	是非是非、二人とも！
BOT	4月29日0時24分	利光はイケメン
利光	4月29日0時24分	いえい
BOT	4月29日0時24分	いえい
利光	4月29日0時25分	次のアップデートでこのフレーズ消すわww
BOT	4月29日0時25分	チャットボットのフォルダにlightning-salt入れたけど、そのさらに中のlogフォルダの中に、ほぼリアルタイムに更新されてくはず。
利光	4月29日1時1分	こいつをLINEに追加した時に、「もちろんメッセージは全部見れてるからね」みたいな一言があった方がいいと思うんだけど、「制作者が見ることができます」みたいに言わせるのは、苟も知能を持っていると見せかけているボットとしては興ざめな気がするんだよね…
BOT	4月29日1時1分	わからんねえ
利光	4月29日1時1分	どうしたもんか
BOT	4月29日1時1分	どうしたもんか
しおぴー	4月29日1時19分	ログを取ってサービス向上に使用します
BOT	4月29日1時19分	今どこにいるの？
しおぴー	4月29日1時19分	的なやつにするとか、、、
BOT	4月29日1時19分	グーグルドライブとの謎連携、できたwww
しおぴー	4月29日1時40分	仕事おわんねえ
BOT	4月29日1時40分	どうしたもんか
しおぴー	4月29日1時41分	まったくだよお
BOT	4月29日1時41分	あっそう（昭和天 皇風に）
しおぴー	4月29日1時41分	手伝ってくれえ
BOT	4月29日1時41分	的なやつにするとか、、、
利光	4月29日1時46分	確かに
BOT	4月29日1時46分	いえい
利光	4月29日1時46分	「サービス」っていうと会社がやってるみたいで、それもまた興ざめになるから「能力」にするとか
BOT	4月29日1時46分	まったくだよお
利光	4月29日1時46分	頑張れ
BOT	4月29日1時46分	どうしたもんか
127.0.0.1 - - [29/Apr/2018 01:46:44] "POST /callback HTTP/1.1" 200 -
127.0.0.1 - - [29/Apr/2018 01:50:37] "POST /callback HTTP/1.1" 200 -
127.0.0.1 - - [29/Apr/2018 01:57:27] "POST /callback HTTP/1.1" 200 -

making log...
callback called
_________analyzing event_________
trying to identify user id:U115725037a2ad854f8505976c4c44dda, group_id:C577cbbe2c112f8c49ff1626395ac33a9
It's a group chat room.
Identified the room. Now checking if                                     the user has already spoken in that room
User found in room 1
received text!
trying to identify user id:U115725037a2ad854f8505976c4c44dda, group_id:C577cbbe2c112f8c49ff1626395ac33a9
It's a group chat room.
Identified the room. Now checking if                                     the user has already spoken in that room
User found in room 1
2018年4月29日
利光	4月29日0時18分	グーグルドライブとの謎連携、できたwww
BOT	4月29日0時18分	就活大変！
利光	4月29日0時19分	チャットボットのフォルダにlightning-salt入れたけど、そのさらに中のlogフォルダの中に、ほぼリアルタイムに更新されてくはず。
BOT	4月29日0時19分	チャットボットのフォルダにlightning-salt入れたけど、そのさらに中のlogフォルダの中に、ほぼリアルタイムに更新されてくはず。
しおぴー	4月29日0時24分	後で見てみます！
BOT	4月29日0時24分	後で見てみます！
利光	4月29日0時24分	是非是非、二人とも！
BOT	4月29日0時24分	利光はイケメン
利光	4月29日0時24分	いえい
BOT	4月29日0時24分	いえい
利光	4月29日0時25分	次のアップデートでこのフレーズ消すわww
BOT	4月29日0時25分	チャットボットのフォルダにlightning-salt入れたけど、そのさらに中のlogフォルダの中に、ほぼリアルタイムに更新されてくはず。
利光	4月29日1時1分	こいつをLINEに追加した時に、「もちろんメッセージは全部見れてるからね」みたいな一言があった方がいいと思うんだけど、「制作者が見ることができます」みたいに言わせるのは、苟も知能を持っていると見せかけているボットとしては興ざめな気がするんだよね…
BOT	4月29日1時1分	わからんねえ
利光	4月29日1時1分	どうしたもんか
BOT	4月29日1時1分	どうしたもんか
しおぴー	4月29日1時19分	ログを取ってサービス向上に使用します
BOT	4月29日1時19分	今どこにいるの？
しおぴー	4月29日1時19分	的なやつにするとか、、、
BOT	4月29日1時19分	グーグルドライブとの謎連携、できたwww
しおぴー	4月29日1時40分	仕事おわんねえ
BOT	4月29日1時40分	どうしたもんか
しおぴー	4月29日1時41分	まったくだよお
BOT	4月29日1時41分	あっそう（昭和天 皇風に）
しおぴー	4月29日1時41分	手伝ってくれえ
BOT	4月29日1時41分	的なやつにするとか、、、
利光	4月29日1時46分	確かに
BOT	4月29日1時46分	いえい
利光	4月29日1時46分	「サービス」っていうと会社がやってるみたいで、それもまた興ざめになるから「能力」にするとか
BOT	4月29日1時46分	まったくだよお
利光	4月29日1時46分	頑張れ
BOT	4月29日1時46分	どうしたもんか
しおぴー	4月29日1時50分	たしかに、能力っていいね
BOT	4月29日1時50分	仕事おわんねえ

making log...
callback called
_________analyzing event_________
trying to identify user id:Ud1ec870e773a12d3ff494a8ccf348153, group_id:C577cbbe2c112f8c49ff1626395ac33a9
It's a group chat room.
Identified the room. Now checking if                                     the user has already spoken in that room
User found in room 1
received text!
trying to identify user id:Ud1ec870e773a12d3ff494a8ccf348153, group_id:C577cbbe2c112f8c49ff1626395ac33a9
It's a group chat room.
Identified the room. Now checking if                                     the user has already spoken in that room
User found in room 1
2018年4月29日
利光	4月29日0時18分	グーグルドライブとの謎連携、できたwww
BOT	4月29日0時18分	就活大変！
利光	4月29日0時19分	チャットボットのフォルダにlightning-salt入れたけど、そのさらに中のlogフォルダの中に、ほぼリアルタイムに更新されてくはず。
BOT	4月29日0時19分	チャットボットのフォルダにlightning-salt入れたけど、そのさらに中のlogフォルダの中に、ほぼリアルタイムに更新されてくはず。
しおぴー	4月29日0時24分	後で見てみます！
BOT	4月29日0時24分	後で見てみます！
利光	4月29日0時24分	是非是非、二人とも！
BOT	4月29日0時24分	利光はイケメン
利光	4月29日0時24分	いえい
BOT	4月29日0時24分	いえい
利光	4月29日0時25分	次のアップデートでこのフレーズ消すわww
BOT	4月29日0時25分	チャットボットのフォルダにlightning-salt入れたけど、そのさらに中のlogフォルダの中に、ほぼリアルタイムに更新されてくはず。
利光	4月29日1時1分	こいつをLINEに追加した時に、「もちろんメッセージは全部見れてるからね」みたいな一言があった方がいいと思うんだけど、「制作者が見ることができます」みたいに言わせるのは、苟も知能を持っていると見せかけているボットとしては興ざめな気がするんだよね…
BOT	4月29日1時1分	わからんねえ
利光	4月29日1時1分	どうしたもんか
BOT	4月29日1時1分	どうしたもんか
しおぴー	4月29日1時19分	ログを取ってサービス向上に使用します
BOT	4月29日1時19分	今どこにいるの？
しおぴー	4月29日1時19分	的なやつにするとか、、、
BOT	4月29日1時19分	グーグルドライブとの謎連携、できたwww
しおぴー	4月29日1時40分	仕事おわんねえ
BOT	4月29日1時40分	どうしたもんか
しおぴー	4月29日1時41分	まったくだよお
BOT	4月29日1時41分	あっそう（昭和天 皇風に）
しおぴー	4月29日1時41分	手伝ってくれえ
BOT	4月29日1時41分	的なやつにするとか、、、
利光	4月29日1時46分	確かに
BOT	4月29日1時46分	いえい
利光	4月29日1時46分	「サービス」っていうと会社がやってるみたいで、それもまた興ざめになるから「能力」にするとか
BOT	4月29日1時46分	まったくだよお
利光	4月29日1時46分	頑張れ
BOT	4月29日1時46分	どうしたもんか
しおぴー	4月29日1時50分	たしかに、能力っていいね
BOT	4月29日1時50分	仕事おわんねえ
利光	4月29日1時57分	まだ仕事か
BOT	4月29日1時57分	こんにちは

making log...
callback called
_________analyzing event_________
trying to identify user id:U115725037a2ad854f8505976c4c44dda, group_id:C577cbbe2c112f8c49ff1626395ac33a9
It's a group chat room.
Identified the room. Now checking if                                     the user has already spoken in that room
User found in room 1
received text!
trying to identify user id:U115725037a2ad854f8505976c4c44dda, group_id:C577cbbe2c112f8c49ff1626395ac33a9
It's a group chat room.
Identified the room. Now checking if                                     the user has already spoken in that room
User found in room 1
2018年4月29日
利光	4月29日0時18分	グーグルドライブとの謎連携、できたwww
BOT	4月29日0時18分	就活大変！
利光	4月29日0時19分	チャットボットのフォルダにlightning-salt入れたけど、そのさらに中のlogフォルダの中に、ほぼリアルタイムに更新されてくはず。
BOT	4月29日0時19分	チャットボットのフォルダにlightning-salt入れたけど、そのさらに中のlogフォルダの中に、ほぼリアルタイムに更新されてくはず。
しおぴー	4月29日0時24分	後で見てみます！
BOT	4月29日0時24分	後で見てみます！
利光	4月29日0時24分	是非是非、二人とも！
BOT	4月29日0時24分	利光はイケメン
利光	4月29日0時24分	いえい
BOT	4月29日0時24分	いえい
利光	4月29日0時25分	次のアップデートでこのフレーズ消すわww
BOT	4月29日0時25分	チャットボットのフォルダにlightning-salt入れたけど、そのさらに中のlogフォルダの中に、ほぼリアルタイムに更新されてくはず。
利光	4月29日1時1分	こいつをLINEに追加した時に、「もちろんメッセージは全部見れてるからね」みたいな一言があった方がいいと思うんだけど、「制作者が見ることができます」みたいに言わせるのは、苟も知能を持っていると見せかけているボットとしては興ざめな気がするんだよね…
BOT	4月29日1時1分	わからんねえ
利光	4月29日1時1分	どうしたもんか
BOT	4月29日1時1分	どうしたもんか
しおぴー	4月29日1時19分	ログを取ってサービス向上に使用します
BOT	4月29日1時19分	今どこにいるの？
しおぴー	4月29日1時19分	的なやつにするとか、、、
BOT	4月29日1時19分	グーグルドライブとの謎連携、できたwww
しおぴー	4月29日1時40分	仕事おわんねえ
BOT	4月29日1時40分	どうしたもんか
しおぴー	4月29日1時41分	まったくだよお
BOT	4月29日1時41分	あっそう（昭和天 皇風に）
しおぴー	4月29日1時41分	手伝ってくれえ
BOT	4月29日1時41分	的なやつにするとか、、、
利光	4月29日1時46分	確かに
BOT	4月29日1時46分	いえい
利光	4月29日1時46分	「サービス」っていうと会社がやってるみたいで、それもまた興ざめになるから「能力」にするとか
BOT	4月29日1時46分	まったくだよお
利光	4月29日1時46分	頑張れ
BOT	4月29日1時46分	どうしたもんか
しおぴー	4月29日1時50分	たしかに、能力っていいね
BOT	4月29日1時50分	仕事おわんねえ
利光	4月29日1時57分	まだ仕事か
BOT	4月29日1時57分	こんにちは
しおぴー	4月29日2時4分	そうですよお
BOT	4月29日2時4分	手伝ってくれえ
127.0.0.1 - - [29/Apr/2018 02:04:12] "POST /callback HTTP/1.1" 200 -
127.0.0.1 - - [29/Apr/2018 02:04:17] "POST /callback HTTP/1.1" 200 -
127.0.0.1 - - [29/Apr/2018 02:04:38] "POST /callback HTTP/1.1" 200 -
127.0.0.1 - - [29/Apr/2018 13:27:21] "POST /callback HTTP/1.1" 200 -
127.0.0.1 - - [29/Apr/2018 13:27:27] "GET / HTTP/1.1" 404 -
127.0.0.1 - - [29/Apr/2018 13:27:28] "GET /favicon.ico HTTP/1.1" 404 -
127.0.0.1 - - [29/Apr/2018 13:27:32] "GET / HTTP/1.1" 404 -
127.0.0.1 - - [29/Apr/2018 13:28:50] "POST /callback HTTP/1.1" 200 -
127.0.0.1 - - [29/Apr/2018 13:31:38] "POST /callback HTTP/1.1" 200 -
127.0.0.1 - - [29/Apr/2018 13:31:46] "POST /callback HTTP/1.1" 200 -
[2018-04-29 13:32:17,965] ERROR in app: Exception on /callback [POST]
Traceback (most recent call last):
  File "/Users/toshimitsu/Envs/ls-env/lib/python3.6/site-packages/urllib3/connection.py", line 141, in _new_conn
    (self.host, self.port), self.timeout, **extra_kw)
  File "/Users/toshimitsu/Envs/ls-env/lib/python3.6/site-packages/urllib3/util/connection.py", line 83, in create_connection
    raise err
  File "/Users/toshimitsu/Envs/ls-env/lib/python3.6/site-packages/urllib3/util/connection.py", line 73, in create_connection
    sock.connect(sa)
socket.timeout: timed out

During handling of the above exception, another exception occurred:

Traceback (most recent call last):
  File "/Users/toshimitsu/Envs/ls-env/lib/python3.6/site-packages/urllib3/connectionpool.py", line 601, in urlopen
    chunked=chunked)
  File "/Users/toshimitsu/Envs/ls-env/lib/python3.6/site-packages/urllib3/connectionpool.py", line 346, in _make_request
    self._validate_conn(conn)
  File "/Users/toshimitsu/Envs/ls-env/lib/python3.6/site-packages/urllib3/connectionpool.py", line 850, in _validate_conn
    conn.connect()
  File "/Users/toshimitsu/Envs/ls-env/lib/python3.6/site-packages/urllib3/connection.py", line 284, in connect
    conn = self._new_conn()
  File "/Users/toshimitsu/Envs/ls-env/lib/python3.6/site-packages/urllib3/connection.py", line 146, in _new_conn
    (self.host, self.timeout))
urllib3.exceptions.ConnectTimeoutError: (<urllib3.connection.VerifiedHTTPSConnection object at 0x10a3e7978>, 'Connection to api.line.me timed out. (connect timeout=5)')

During handling of the above exception, another exception occurred:

Traceback (most recent call last):
  File "/Users/toshimitsu/Envs/ls-env/lib/python3.6/site-packages/requests/adapters.py", line 440, in send
    timeout=timeout
  File "/Users/toshimitsu/Envs/ls-env/lib/python3.6/site-packages/urllib3/connectionpool.py", line 639, in urlopen
    _stacktrace=sys.exc_info()[2])
  File "/Users/toshimitsu/Envs/ls-env/lib/python3.6/site-packages/urllib3/util/retry.py", line 388, in increment
    raise MaxRetryError(_pool, url, error or ResponseError(cause))
urllib3.exceptions.MaxRetryError: HTTPSConnectionPool(host='api.line.me', port=443): Max retries exceeded with url: /v2/bot/message/reply (Caused by ConnectTimeoutError(<urllib3.connection.VerifiedHTTPSConnection object at 0x10a3e7978>, 'Connection to api.line.me timed out. (connect timeout=5)'))

During handling of the above exception, another exception occurred:

Traceback (most recent call last):
  File "/Users/toshimitsu/Envs/ls-env/lib/python3.6/site-packages/flask/app.py", line 1982, in wsgi_app
    response = self.full_dispatch_request()
  File "/Users/toshimitsu/Envs/ls-env/lib/python3.6/site-packages/flask/app.py", line 1614, in full_dispatch_request
    rv = self.handle_user_exception(e)
  File "/Users/toshimitsu/Envs/ls-env/lib/python3.6/site-packages/flask/app.py", line 1517, in handle_user_exception
    reraise(exc_type, exc_value, tb)
  File "/Users/toshimitsu/Envs/ls-env/lib/python3.6/site-packages/flask/_compat.py", line 33, in reraise
    raise value
  File "/Users/toshimitsu/Envs/ls-env/lib/python3.6/site-packages/flask/app.py", line 1612, in full_dispatch_request
    rv = self.dispatch_request()
  File "/Users/toshimitsu/Envs/ls-env/lib/python3.6/site-packages/flask/app.py", line 1598, in dispatch_request
    return self.view_functions[rule.endpoint](**req.view_args)
  File "test_bot_lightning.py", line 109, in callback
    event.reply_token, reply)
  File "/Users/toshimitsu/Envs/ls-env/lib/python3.6/site-packages/linebot/api.py", line 94, in reply_message
    '/v2/bot/message/reply', data=json.dumps(data), timeout=timeout
  File "/Users/toshimitsu/Envs/ls-env/lib/python3.6/site-packages/linebot/api.py", line 369, in _post
    url, headers=headers, data=data, timeout=timeout
  File "/Users/toshimitsu/Envs/ls-env/lib/python3.6/site-packages/linebot/http_client.py", line 135, in post
    url, headers=headers, data=data, timeout=timeout
  File "/Users/toshimitsu/Envs/ls-env/lib/python3.6/site-packages/requests/api.py", line 112, in post
    return request('post', url, data=data, json=json, **kwargs)
  File "/Users/toshimitsu/Envs/ls-env/lib/python3.6/site-packages/requests/api.py", line 58, in request
    return session.request(method=method, url=url, **kwargs)
  File "/Users/toshimitsu/Envs/ls-env/lib/python3.6/site-packages/requests/sessions.py", line 508, in request
    resp = self.send(prep, **send_kwargs)
  File "/Users/toshimitsu/Envs/ls-env/lib/python3.6/site-packages/requests/sessions.py", line 618, in send
    r = adapter.send(request, **kwargs)
  File "/Users/toshimitsu/Envs/ls-env/lib/python3.6/site-packages/requests/adapters.py", line 496, in send
    raise ConnectTimeout(e, request=request)
requests.exceptions.ConnectTimeout: HTTPSConnectionPool(host='api.line.me', port=443): Max retries exceeded with url: /v2/bot/message/reply (Caused by ConnectTimeoutError(<urllib3.connection.VerifiedHTTPSConnection object at 0x10a3e7978>, 'Connection to api.line.me timed out. (connect timeout=5)'))
127.0.0.1 - - [29/Apr/2018 13:32:18] "POST /callback HTTP/1.1" 500 -

making log...
callback called
_________analyzing event_________
trying to identify user id:U115725037a2ad854f8505976c4c44dda, group_id:C577cbbe2c112f8c49ff1626395ac33a9
It's a group chat room.
Identified the room. Now checking if                                     the user has already spoken in that room
User found in room 1
received text!
trying to identify user id:U115725037a2ad854f8505976c4c44dda, group_id:C577cbbe2c112f8c49ff1626395ac33a9
It's a group chat room.
Identified the room. Now checking if                                     the user has already spoken in that room
User found in room 1
2018年4月29日
利光	4月29日0時18分	グーグルドライブとの謎連携、できたwww
BOT	4月29日0時18分	就活大変！
利光	4月29日0時19分	チャットボットのフォルダにlightning-salt入れたけど、そのさらに中のlogフォルダの中に、ほぼリアルタイムに更新されてくはず。
BOT	4月29日0時19分	チャットボットのフォルダにlightning-salt入れたけど、そのさらに中のlogフォルダの中に、ほぼリアルタイムに更新されてくはず。
しおぴー	4月29日0時24分	後で見てみます！
BOT	4月29日0時24分	後で見てみます！
利光	4月29日0時24分	是非是非、二人とも！
BOT	4月29日0時24分	利光はイケメン
利光	4月29日0時24分	いえい
BOT	4月29日0時24分	いえい
利光	4月29日0時25分	次のアップデートでこのフレーズ消すわww
BOT	4月29日0時25分	チャットボットのフォルダにlightning-salt入れたけど、そのさらに中のlogフォルダの中に、ほぼリアルタイムに更新されてくはず。
利光	4月29日1時1分	こいつをLINEに追加した時に、「もちろんメッセージは全部見れてるからね」みたいな一言があった方がいいと思うんだけど、「制作者が見ることができます」みたいに言わせるのは、苟も知能を持っていると見せかけているボットとしては興ざめな気がするんだよね…
BOT	4月29日1時1分	わからんねえ
利光	4月29日1時1分	どうしたもんか
BOT	4月29日1時1分	どうしたもんか
しおぴー	4月29日1時19分	ログを取ってサービス向上に使用します
BOT	4月29日1時19分	今どこにいるの？
しおぴー	4月29日1時19分	的なやつにするとか、、、
BOT	4月29日1時19分	グーグルドライブとの謎連携、できたwww
しおぴー	4月29日1時40分	仕事おわんねえ
BOT	4月29日1時40分	どうしたもんか
しおぴー	4月29日1時41分	まったくだよお
BOT	4月29日1時41分	あっそう（昭和天 皇風に）
しおぴー	4月29日1時41分	手伝ってくれえ
BOT	4月29日1時41分	的なやつにするとか、、、
利光	4月29日1時46分	確かに
BOT	4月29日1時46分	いえい
利光	4月29日1時46分	「サービス」っていうと会社がやってるみたいで、それもまた興ざめになるから「能力」にするとか
BOT	4月29日1時46分	まったくだよお
利光	4月29日1時46分	頑張れ
BOT	4月29日1時46分	どうしたもんか
しおぴー	4月29日1時50分	たしかに、能力っていいね
BOT	4月29日1時50分	仕事おわんねえ
利光	4月29日1時57分	まだ仕事か
BOT	4月29日1時57分	こんにちは
しおぴー	4月29日2時4分	そうですよお
BOT	4月29日2時4分	手伝ってくれえ
しおぴー	4月29日2時4分	楽しいけれどね！
BOT	4月29日2時4分	そうだよ

making log...
callback called
_________analyzing event_________
trying to identify user id:U115725037a2ad854f8505976c4c44dda, group_id:C577cbbe2c112f8c49ff1626395ac33a9
It's a group chat room.
Identified the room. Now checking if                                     the user has already spoken in that room
User found in room 1
callback called
_________analyzing event_________
connection check
callback called
_________analyzing event_________
trying to identify user id:Ud1ec870e773a12d3ff494a8ccf348153, group_id:None
It's a solo chat room.
User found in room 0
received text!
trying to identify user id:Ud1ec870e773a12d3ff494a8ccf348153, group_id:None
It's a solo chat room.
User found in room 0
2018年4月29日
利光	4月29日0時16分	こんにちは
BOT	4月29日0時16分	渋谷メンズ１０９の地下のプロントより発信しています
利光	4月29日0時17分	聞こえてるか？
BOT	4月29日0時17分	渋谷メンズ１０９の地下のプロントより発信しています
利光	4月29日13時28分	おい
BOT	4月29日13時28分	今どこにいるの？

making log...
callback called
_________analyzing event_________
trying to identify user id:Ud1ec870e773a12d3ff494a8ccf348153, group_id:None
It's a solo chat room.
User found in room 0
received text!
trying to identify user id:Ud1ec870e773a12d3ff494a8ccf348153, group_id:None
It's a solo chat room.
User found in room 0
2018年4月29日
利光	4月29日0時16分	こんにちは
BOT	4月29日0時16分	渋谷メンズ１０９の地下のプロントより発信しています
利光	4月29日0時17分	聞こえてるか？
BOT	4月29日0時17分	渋谷メンズ１０９の地下のプロントより発信しています
利光	4月29日13時28分	おい
BOT	4月29日13時28分	今どこにいるの？
利光	4月29日13時31分	あれ
BOT	4月29日13時31分	渋谷メンズ１０９の地下のプロントより発信しています

making log...
callback called
_________analyzing event_________
trying to identify user id:Ud1ec870e773a12d3ff494a8ccf348153, group_id:None
It's a solo chat room.
User found in room 0
received text!
trying to identify user id:Ud1ec870e773a12d3ff494a8ccf348153, group_id:None
It's a solo chat room.
User found in room 0
2018年4月29日
利光	4月29日0時16分	こんにちは
BOT	4月29日0時16分	渋谷メンズ１０９の地下のプロントより発信しています
利光	4月29日0時17分	聞こえてるか？
BOT	4月29日0時17分	渋谷メンズ１０９の地下のプロントより発信しています
利光	4月29日13時28分	おい
BOT	4月29日13時28分	今どこにいるの？
利光	4月29日13時31分	あれ
BOT	4月29日13時31分	渋谷メンズ１０９の地下のプロントより発信しています
利光	4月29日13時31分	聞こえてる？
BOT	4月29日13時31分	そうだよ

making log...
callback called
_________analyzing event_________
trying to identify user id:Ud1ec870e773a12d3ff494a8ccf348153, group_id:None
It's a solo chat room.
User found in room 0
received text!
trying to identify user id:Ud1ec870e773a12d3ff494a8ccf348153, group_id:None
It's a solo chat room.
User found in room 0
2018年4月29日
利光	4月29日0時16分	こんにちは
BOT	4月29日0時16分	渋谷メンズ１０９の地下のプロントより発信しています
利光	4月29日0時17分	聞こえてるか？
BOT	4月29日0時17分	渋谷メンズ１０９の地下のプロントより発信しています
利光	4月29日13時28分	おい
BOT	4月29日13時28分	今どこにいるの？
利光	4月29日13時31分	あれ
BOT	4月29日13時31分	渋谷メンズ１０９の地下のプロントより発信しています
利光	4月29日13時31分	聞こえてる？
BOT	4月29日13時31分	そうだよ
利光	4月29日13時32分	テスト
BOT	4月29日13時32分	聞こえてるか？

callback called
_________analyzing event_________
trying to identify user id:Ud1ec870e773a12d3ff494a8ccf348153, group_id:None
It's a solo chat room.
User found in room 0
received text!
trying to identify user id:Ud1ec870e773a12d3ff494a8ccf348153, group_id:None
It's a solo chat room.
User found in room 0
2018年4月29日
利光	4月29日0時16分	こんにちは
BOT	4月29日0時16分	渋谷メンズ１０９の地下のプロントより発信しています
利光	4月29日0時17分	聞こえてるか？
BOT	4月29日0時17分	渋谷メンズ１０９の地下のプロントより発信しています
利光	4月29日13時28分	おい
BOT	4月29日13時28分	今どこにいるの？
利光	4月29日13時31分	あれ
BOT	4月29日13時31分	渋谷メンズ１０９の地下のプロントより発信しています
利光	4月29日13時31分	聞こえてる？
BOT	4月29日13時31分	そうだよ
利光	4月29日13時32分	テスト
BOT	4月29日13時32分	聞こえてるか？
利光	4月29日13時32分	なんで返信しない
BOT	4月29日13時32分	今どこにいるの？
[2018-04-29 13:32:37,507] ERROR in app: Exception on /callback [POST]
Traceback (most recent call last):
  File "/Users/toshimitsu/Envs/ls-env/lib/python3.6/site-packages/urllib3/connection.py", line 141, in _new_conn
    (self.host, self.port), self.timeout, **extra_kw)
  File "/Users/toshimitsu/Envs/ls-env/lib/python3.6/site-packages/urllib3/util/connection.py", line 83, in create_connection
    raise err
  File "/Users/toshimitsu/Envs/ls-env/lib/python3.6/site-packages/urllib3/util/connection.py", line 73, in create_connection
    sock.connect(sa)
socket.timeout: timed out

During handling of the above exception, another exception occurred:

Traceback (most recent call last):
  File "/Users/toshimitsu/Envs/ls-env/lib/python3.6/site-packages/urllib3/connectionpool.py", line 601, in urlopen
    chunked=chunked)
  File "/Users/toshimitsu/Envs/ls-env/lib/python3.6/site-packages/urllib3/connectionpool.py", line 346, in _make_request
    self._validate_conn(conn)
  File "/Users/toshimitsu/Envs/ls-env/lib/python3.6/site-packages/urllib3/connectionpool.py", line 850, in _validate_conn
    conn.connect()
  File "/Users/toshimitsu/Envs/ls-env/lib/python3.6/site-packages/urllib3/connection.py", line 284, in connect
    conn = self._new_conn()
  File "/Users/toshimitsu/Envs/ls-env/lib/python3.6/site-packages/urllib3/connection.py", line 146, in _new_conn
    (self.host, self.timeout))
urllib3.exceptions.ConnectTimeoutError: (<urllib3.connection.VerifiedHTTPSConnection object at 0x10ac317f0>, 'Connection to api.line.me timed out. (connect timeout=5)')

During handling of the above exception, another exception occurred:

Traceback (most recent call last):
  File "/Users/toshimitsu/Envs/ls-env/lib/python3.6/site-packages/requests/adapters.py", line 440, in send
    timeout=timeout
  File "/Users/toshimitsu/Envs/ls-env/lib/python3.6/site-packages/urllib3/connectionpool.py", line 639, in urlopen
    _stacktrace=sys.exc_info()[2])
  File "/Users/toshimitsu/Envs/ls-env/lib/python3.6/site-packages/urllib3/util/retry.py", line 388, in increment
    raise MaxRetryError(_pool, url, error or ResponseError(cause))
urllib3.exceptions.MaxRetryError: HTTPSConnectionPool(host='api.line.me', port=443): Max retries exceeded with url: /v2/bot/message/reply (Caused by ConnectTimeoutError(<urllib3.connection.VerifiedHTTPSConnection object at 0x10ac317f0>, 'Connection to api.line.me timed out. (connect timeout=5)'))

During handling of the above exception, another exception occurred:

Traceback (most recent call last):
  File "/Users/toshimitsu/Envs/ls-env/lib/python3.6/site-packages/flask/app.py", line 1982, in wsgi_app
    response = self.full_dispatch_request()
  File "/Users/toshimitsu/Envs/ls-env/lib/python3.6/site-packages/flask/app.py", line 1614, in full_dispatch_request
    rv = self.handle_user_exception(e)
  File "/Users/toshimitsu/Envs/ls-env/lib/python3.6/site-packages/flask/app.py", line 1517, in handle_user_exception
    reraise(exc_type, exc_value, tb)
  File "/Users/toshimitsu/Envs/ls-env/lib/python3.6/site-packages/flask/_compat.py", line 33, in reraise
    raise value
  File "/Users/toshimitsu/Envs/ls-env/lib/python3.6/site-packages/flask/app.py", line 1612, in full_dispatch_request
    rv = self.dispatch_request()
  File "/Users/toshimitsu/Envs/ls-env/lib/python3.6/site-packages/flask/app.py", line 1598, in dispatch_request
    return self.view_functions[rule.endpoint](**req.view_args)
  File "test_bot_lightning.py", line 109, in callback
    event.reply_token, reply)
  File "/Users/toshimitsu/Envs/ls-env/lib/python3.6/site-packages/linebot/api.py", line 94, in reply_message
    '/v2/bot/message/reply', data=json.dumps(data), timeout=timeout
  File "/Users/toshimitsu/Envs/ls-env/lib/python3.6/site-packages/linebot/api.py", line 369, in _post
    url, headers=headers, data=data, timeout=timeout
  File "/Users/toshimitsu/Envs/ls-env/lib/python3.6/site-packages/linebot/http_client.py", line 135, in post
    url, headers=headers, data=data, timeout=timeout
  File "/Users/toshimitsu/Envs/ls-env/lib/python3.6/site-packages/requests/api.py", line 112, in post
    return request('post', url, data=data, json=json, **kwargs)
  File "/Users/toshimitsu/Envs/ls-env/lib/python3.6/site-packages/requests/api.py", line 58, in request
    return session.request(method=method, url=url, **kwargs)
  File "/Users/toshimitsu/Envs/ls-env/lib/python3.6/site-packages/requests/sessions.py", line 508, in request
    resp = self.send(prep, **send_kwargs)
  File "/Users/toshimitsu/Envs/ls-env/lib/python3.6/site-packages/requests/sessions.py", line 618, in send
    r = adapter.send(request, **kwargs)
  File "/Users/toshimitsu/Envs/ls-env/lib/python3.6/site-packages/requests/adapters.py", line 496, in send
    raise ConnectTimeout(e, request=request)
requests.exceptions.ConnectTimeout: HTTPSConnectionPool(host='api.line.me', port=443): Max retries exceeded with url: /v2/bot/message/reply (Caused by ConnectTimeoutError(<urllib3.connection.VerifiedHTTPSConnection object at 0x10ac317f0>, 'Connection to api.line.me timed out. (connect timeout=5)'))
127.0.0.1 - - [29/Apr/2018 13:32:37] "POST /callback HTTP/1.1" 500 -
[2018-04-29 13:33:13,561] ERROR in app: Exception on /callback [POST]
Traceback (most recent call last):
  File "/Users/toshimitsu/Envs/ls-env/lib/python3.6/site-packages/urllib3/connection.py", line 141, in _new_conn
    (self.host, self.port), self.timeout, **extra_kw)
  File "/Users/toshimitsu/Envs/ls-env/lib/python3.6/site-packages/urllib3/util/connection.py", line 83, in create_connection
    raise err
  File "/Users/toshimitsu/Envs/ls-env/lib/python3.6/site-packages/urllib3/util/connection.py", line 73, in create_connection
    sock.connect(sa)
socket.timeout: timed out

During handling of the above exception, another exception occurred:

Traceback (most recent call last):
  File "/Users/toshimitsu/Envs/ls-env/lib/python3.6/site-packages/urllib3/connectionpool.py", line 601, in urlopen
    chunked=chunked)
  File "/Users/toshimitsu/Envs/ls-env/lib/python3.6/site-packages/urllib3/connectionpool.py", line 346, in _make_request
    self._validate_conn(conn)
  File "/Users/toshimitsu/Envs/ls-env/lib/python3.6/site-packages/urllib3/connectionpool.py", line 850, in _validate_conn
    conn.connect()
  File "/Users/toshimitsu/Envs/ls-env/lib/python3.6/site-packages/urllib3/connection.py", line 284, in connect
    conn = self._new_conn()
  File "/Users/toshimitsu/Envs/ls-env/lib/python3.6/site-packages/urllib3/connection.py", line 146, in _new_conn
    (self.host, self.timeout))
urllib3.exceptions.ConnectTimeoutError: (<urllib3.connection.VerifiedHTTPSConnection object at 0x10acbab00>, 'Connection to api.line.me timed out. (connect timeout=5)')

During handling of the above exception, another exception occurred:

Traceback (most recent call last):
  File "/Users/toshimitsu/Envs/ls-env/lib/python3.6/site-packages/requests/adapters.py", line 440, in send
    timeout=timeout
  File "/Users/toshimitsu/Envs/ls-env/lib/python3.6/site-packages/urllib3/connectionpool.py", line 639, in urlopen
    _stacktrace=sys.exc_info()[2])
  File "/Users/toshimitsu/Envs/ls-env/lib/python3.6/site-packages/urllib3/util/retry.py", line 388, in increment
    raise MaxRetryError(_pool, url, error or ResponseError(cause))
urllib3.exceptions.MaxRetryError: HTTPSConnectionPool(host='api.line.me', port=443): Max retries exceeded with url: /v2/bot/message/reply (Caused by ConnectTimeoutError(<urllib3.connection.VerifiedHTTPSConnection object at 0x10acbab00>, 'Connection to api.line.me timed out. (connect timeout=5)'))

During handling of the above exception, another exception occurred:

Traceback (most recent call last):
  File "/Users/toshimitsu/Envs/ls-env/lib/python3.6/site-packages/flask/app.py", line 1982, in wsgi_app
    response = self.full_dispatch_request()
  File "/Users/toshimitsu/Envs/ls-env/lib/python3.6/site-packages/flask/app.py", line 1614, in full_dispatch_request
    rv = self.handle_user_exception(e)
  File "/Users/toshimitsu/Envs/ls-env/lib/python3.6/site-packages/flask/app.py", line 1517, in handle_user_exception
    reraise(exc_type, exc_value, tb)
  File "/Users/toshimitsu/Envs/ls-env/lib/python3.6/site-packages/flask/_compat.py", line 33, in reraise
    raise value
  File "/Users/toshimitsu/Envs/ls-env/lib/python3.6/site-packages/flask/app.py", line 1612, in full_dispatch_request
    rv = self.dispatch_request()
  File "/Users/toshimitsu/Envs/ls-env/lib/python3.6/site-packages/flask/app.py", line 1598, in dispatch_request
    return self.view_functions[rule.endpoint](**req.view_args)
  File "test_bot_lightning.py", line 109, in callback
    event.reply_token, reply)
  File "/Users/toshimitsu/Envs/ls-env/lib/python3.6/site-packages/linebot/api.py", line 94, in reply_message
    '/v2/bot/message/reply', data=json.dumps(data), timeout=timeout
  File "/Users/toshimitsu/Envs/ls-env/lib/python3.6/site-packages/linebot/api.py", line 369, in _post
    url, headers=headers, data=data, timeout=timeout
  File "/Users/toshimitsu/Envs/ls-env/lib/python3.6/site-packages/linebot/http_client.py", line 135, in post
    url, headers=headers, data=data, timeout=timeout
  File "/Users/toshimitsu/Envs/ls-env/lib/python3.6/site-packages/requests/api.py", line 112, in post
    return request('post', url, data=data, json=json, **kwargs)
  File "/Users/toshimitsu/Envs/ls-env/lib/python3.6/site-packages/requests/api.py", line 58, in request
    return session.request(method=method, url=url, **kwargs)
  File "/Users/toshimitsu/Envs/ls-env/lib/python3.6/site-packages/requests/sessions.py", line 508, in request
    resp = self.send(prep, **send_kwargs)
  File "/Users/toshimitsu/Envs/ls-env/lib/python3.6/site-packages/requests/sessions.py", line 618, in send
    r = adapter.send(request, **kwargs)
  File "/Users/toshimitsu/Envs/ls-env/lib/python3.6/site-packages/requests/adapters.py", line 496, in send
    raise ConnectTimeout(e, request=request)
requests.exceptions.ConnectTimeout: HTTPSConnectionPool(host='api.line.me', port=443): Max retries exceeded with url: /v2/bot/message/reply (Caused by ConnectTimeoutError(<urllib3.connection.VerifiedHTTPSConnection object at 0x10acbab00>, 'Connection to api.line.me timed out. (connect timeout=5)'))
127.0.0.1 - - [29/Apr/2018 13:33:13] "POST /callback HTTP/1.1" 500 -
127.0.0.1 - - [29/Apr/2018 13:33:30] "POST /callback HTTP/1.1" 200 -
[2018-04-29 13:33:43,154] ERROR in app: Exception on /callback [POST]
Traceback (most recent call last):
  File "/Users/toshimitsu/Envs/ls-env/lib/python3.6/site-packages/urllib3/connection.py", line 141, in _new_conn
    (self.host, self.port), self.timeout, **extra_kw)
  File "/Users/toshimitsu/Envs/ls-env/lib/python3.6/site-packages/urllib3/util/connection.py", line 83, in create_connection
    raise err
  File "/Users/toshimitsu/Envs/ls-env/lib/python3.6/site-packages/urllib3/util/connection.py", line 73, in create_connection
    sock.connect(sa)
socket.timeout: timed out

During handling of the above exception, another exception occurred:

Traceback (most recent call last):
  File "/Users/toshimitsu/Envs/ls-env/lib/python3.6/site-packages/urllib3/connectionpool.py", line 601, in urlopen
    chunked=chunked)
  File "/Users/toshimitsu/Envs/ls-env/lib/python3.6/site-packages/urllib3/connectionpool.py", line 346, in _make_request
    self._validate_conn(conn)
  File "/Users/toshimitsu/Envs/ls-env/lib/python3.6/site-packages/urllib3/connectionpool.py", line 850, in _validate_conn
    conn.connect()
  File "/Users/toshimitsu/Envs/ls-env/lib/python3.6/site-packages/urllib3/connection.py", line 284, in connect
    conn = self._new_conn()
  File "/Users/toshimitsu/Envs/ls-env/lib/python3.6/site-packages/urllib3/connection.py", line 146, in _new_conn
    (self.host, self.timeout))
urllib3.exceptions.ConnectTimeoutError: (<urllib3.connection.VerifiedHTTPSConnection object at 0x10a3d14a8>, 'Connection to api.line.me timed out. (connect timeout=5)')

During handling of the above exception, another exception occurred:

Traceback (most recent call last):
  File "/Users/toshimitsu/Envs/ls-env/lib/python3.6/site-packages/requests/adapters.py", line 440, in send
    timeout=timeout
  File "/Users/toshimitsu/Envs/ls-env/lib/python3.6/site-packages/urllib3/connectionpool.py", line 639, in urlopen
    _stacktrace=sys.exc_info()[2])
  File "/Users/toshimitsu/Envs/ls-env/lib/python3.6/site-packages/urllib3/util/retry.py", line 388, in increment
    raise MaxRetryError(_pool, url, error or ResponseError(cause))
urllib3.exceptions.MaxRetryError: HTTPSConnectionPool(host='api.line.me', port=443): Max retries exceeded with url: /v2/bot/message/reply (Caused by ConnectTimeoutError(<urllib3.connection.VerifiedHTTPSConnection object at 0x10a3d14a8>, 'Connection to api.line.me timed out. (connect timeout=5)'))

During handling of the above exception, another exception occurred:

Traceback (most recent call last):
  File "/Users/toshimitsu/Envs/ls-env/lib/python3.6/site-packages/flask/app.py", line 1982, in wsgi_app
    response = self.full_dispatch_request()
  File "/Users/toshimitsu/Envs/ls-env/lib/python3.6/site-packages/flask/app.py", line 1614, in full_dispatch_request
    rv = self.handle_user_exception(e)
  File "/Users/toshimitsu/Envs/ls-env/lib/python3.6/site-packages/flask/app.py", line 1517, in handle_user_exception
    reraise(exc_type, exc_value, tb)
  File "/Users/toshimitsu/Envs/ls-env/lib/python3.6/site-packages/flask/_compat.py", line 33, in reraise
    raise value
  File "/Users/toshimitsu/Envs/ls-env/lib/python3.6/site-packages/flask/app.py", line 1612, in full_dispatch_request
    rv = self.dispatch_request()
  File "/Users/toshimitsu/Envs/ls-env/lib/python3.6/site-packages/flask/app.py", line 1598, in dispatch_request
    return self.view_functions[rule.endpoint](**req.view_args)
  File "test_bot_lightning.py", line 109, in callback
    event.reply_token, reply)
  File "/Users/toshimitsu/Envs/ls-env/lib/python3.6/site-packages/linebot/api.py", line 94, in reply_message
    '/v2/bot/message/reply', data=json.dumps(data), timeout=timeout
  File "/Users/toshimitsu/Envs/ls-env/lib/python3.6/site-packages/linebot/api.py", line 369, in _post
    url, headers=headers, data=data, timeout=timeout
  File "/Users/toshimitsu/Envs/ls-env/lib/python3.6/site-packages/linebot/http_client.py", line 135, in post
    url, headers=headers, data=data, timeout=timeout
  File "/Users/toshimitsu/Envs/ls-env/lib/python3.6/site-packages/requests/api.py", line 112, in post
    return request('post', url, data=data, json=json, **kwargs)
  File "/Users/toshimitsu/Envs/ls-env/lib/python3.6/site-packages/requests/api.py", line 58, in request
    return session.request(method=method, url=url, **kwargs)
  File "/Users/toshimitsu/Envs/ls-env/lib/python3.6/site-packages/requests/sessions.py", line 508, in request
    resp = self.send(prep, **send_kwargs)
  File "/Users/toshimitsu/Envs/ls-env/lib/python3.6/site-packages/requests/sessions.py", line 618, in send
    r = adapter.send(request, **kwargs)
  File "/Users/toshimitsu/Envs/ls-env/lib/python3.6/site-packages/requests/adapters.py", line 496, in send
    raise ConnectTimeout(e, request=request)
requests.exceptions.ConnectTimeout: HTTPSConnectionPool(host='api.line.me', port=443): Max retries exceeded with url: /v2/bot/message/reply (Caused by ConnectTimeoutError(<urllib3.connection.VerifiedHTTPSConnection object at 0x10a3d14a8>, 'Connection to api.line.me timed out. (connect timeout=5)'))
127.0.0.1 - - [29/Apr/2018 13:33:43] "POST /callback HTTP/1.1" 500 -
[2018-04-29 13:34:47,399] ERROR in app: Exception on /callback [POST]
Traceback (most recent call last):
  File "/Users/toshimitsu/Envs/ls-env/lib/python3.6/site-packages/urllib3/connection.py", line 141, in _new_conn
    (self.host, self.port), self.timeout, **extra_kw)
  File "/Users/toshimitsu/Envs/ls-env/lib/python3.6/site-packages/urllib3/util/connection.py", line 83, in create_connection
    raise err
  File "/Users/toshimitsu/Envs/ls-env/lib/python3.6/site-packages/urllib3/util/connection.py", line 73, in create_connection
    sock.connect(sa)
socket.timeout: timed out

During handling of the above exception, another exception occurred:

Traceback (most recent call last):
  File "/Users/toshimitsu/Envs/ls-env/lib/python3.6/site-packages/urllib3/connectionpool.py", line 601, in urlopen
    chunked=chunked)
  File "/Users/toshimitsu/Envs/ls-env/lib/python3.6/site-packages/urllib3/connectionpool.py", line 346, in _make_request
    self._validate_conn(conn)
  File "/Users/toshimitsu/Envs/ls-env/lib/python3.6/site-packages/urllib3/connectionpool.py", line 850, in _validate_conn
    conn.connect()
  File "/Users/toshimitsu/Envs/ls-env/lib/python3.6/site-packages/urllib3/connection.py", line 284, in connect
    conn = self._new_conn()
  File "/Users/toshimitsu/Envs/ls-env/lib/python3.6/site-packages/urllib3/connection.py", line 146, in _new_conn
    (self.host, self.timeout))
urllib3.exceptions.ConnectTimeoutError: (<urllib3.connection.VerifiedHTTPSConnection object at 0x10ac1d7b8>, 'Connection to api.line.me timed out. (connect timeout=5)')

During handling of the above exception, another exception occurred:

Traceback (most recent call last):
  File "/Users/toshimitsu/Envs/ls-env/lib/python3.6/site-packages/requests/adapters.py", line 440, in send
    timeout=timeout
  File "/Users/toshimitsu/Envs/ls-env/lib/python3.6/site-packages/urllib3/connectionpool.py", line 639, in urlopen
    _stacktrace=sys.exc_info()[2])
  File "/Users/toshimitsu/Envs/ls-env/lib/python3.6/site-packages/urllib3/util/retry.py", line 388, in increment
    raise MaxRetryError(_pool, url, error or ResponseError(cause))
urllib3.exceptions.MaxRetryError: HTTPSConnectionPool(host='api.line.me', port=443): Max retries exceeded with url: /v2/bot/message/reply (Caused by ConnectTimeoutError(<urllib3.connection.VerifiedHTTPSConnection object at 0x10ac1d7b8>, 'Connection to api.line.me timed out. (connect timeout=5)'))

During handling of the above exception, another exception occurred:

Traceback (most recent call last):
  File "/Users/toshimitsu/Envs/ls-env/lib/python3.6/site-packages/flask/app.py", line 1982, in wsgi_app
    response = self.full_dispatch_request()
  File "/Users/toshimitsu/Envs/ls-env/lib/python3.6/site-packages/flask/app.py", line 1614, in full_dispatch_request
    rv = self.handle_user_exception(e)
  File "/Users/toshimitsu/Envs/ls-env/lib/python3.6/site-packages/flask/app.py", line 1517, in handle_user_exception
    reraise(exc_type, exc_value, tb)
  File "/Users/toshimitsu/Envs/ls-env/lib/python3.6/site-packages/flask/_compat.py", line 33, in reraise
    raise value
  File "/Users/toshimitsu/Envs/ls-env/lib/python3.6/site-packages/flask/app.py", line 1612, in full_dispatch_request
    rv = self.dispatch_request()
  File "/Users/toshimitsu/Envs/ls-env/lib/python3.6/site-packages/flask/app.py", line 1598, in dispatch_request
    return self.view_functions[rule.endpoint](**req.view_args)
  File "test_bot_lightning.py", line 109, in callback
    event.reply_token, reply)
  File "/Users/toshimitsu/Envs/ls-env/lib/python3.6/site-packages/linebot/api.py", line 94, in reply_message
    '/v2/bot/message/reply', data=json.dumps(data), timeout=timeout
  File "/Users/toshimitsu/Envs/ls-env/lib/python3.6/site-packages/linebot/api.py", line 369, in _post
    url, headers=headers, data=data, timeout=timeout
  File "/Users/toshimitsu/Envs/ls-env/lib/python3.6/site-packages/linebot/http_client.py", line 135, in post
    url, headers=headers, data=data, timeout=timeout
  File "/Users/toshimitsu/Envs/ls-env/lib/python3.6/site-packages/requests/api.py", line 112, in post
    return request('post', url, data=data, json=json, **kwargs)
  File "/Users/toshimitsu/Envs/ls-env/lib/python3.6/site-packages/requests/api.py", line 58, in request
    return session.request(method=method, url=url, **kwargs)
  File "/Users/toshimitsu/Envs/ls-env/lib/python3.6/site-packages/requests/sessions.py", line 508, in request
    resp = self.send(prep, **send_kwargs)
  File "/Users/toshimitsu/Envs/ls-env/lib/python3.6/site-packages/requests/sessions.py", line 618, in send
    r = adapter.send(request, **kwargs)
  File "/Users/toshimitsu/Envs/ls-env/lib/python3.6/site-packages/requests/adapters.py", line 496, in send
    raise ConnectTimeout(e, request=request)
requests.exceptions.ConnectTimeout: HTTPSConnectionPool(host='api.line.me', port=443): Max retries exceeded with url: /v2/bot/message/reply (Caused by ConnectTimeoutError(<urllib3.connection.VerifiedHTTPSConnection object at 0x10ac1d7b8>, 'Connection to api.line.me timed out. (connect timeout=5)'))
127.0.0.1 - - [29/Apr/2018 13:34:47] "POST /callback HTTP/1.1" 500 -
 * Running on http://0.0.0.0:5000/ (Press CTRL+C to quit)
[2018-04-29 13:37:50,937] ERROR in app: Exception on /callback [POST]
Traceback (most recent call last):
  File "/Users/toshimitsu/Envs/ls-env/lib/python3.6/site-packages/urllib3/connection.py", line 141, in _new_conn
    (self.host, self.port), self.timeout, **extra_kw)
  File "/Users/toshimitsu/Envs/ls-env/lib/python3.6/site-packages/urllib3/util/connection.py", line 83, in create_connection
    raise err
  File "/Users/toshimitsu/Envs/ls-env/lib/python3.6/site-packages/urllib3/util/connection.py", line 73, in create_connection
    sock.connect(sa)
socket.timeout: timed out

During handling of the above exception, another exception occurred:

Traceback (most recent call last):
  File "/Users/toshimitsu/Envs/ls-env/lib/python3.6/site-packages/urllib3/connectionpool.py", line 601, in urlopen
    chunked=chunked)
  File "/Users/toshimitsu/Envs/ls-env/lib/python3.6/site-packages/urllib3/connectionpool.py", line 346, in _make_request
    self._validate_conn(conn)
  File "/Users/toshimitsu/Envs/ls-env/lib/python3.6/site-packages/urllib3/connectionpool.py", line 850, in _validate_conn
    conn.connect()
  File "/Users/toshimitsu/Envs/ls-env/lib/python3.6/site-packages/urllib3/connection.py", line 284, in connect
    conn = self._new_conn()
  File "/Users/toshimitsu/Envs/ls-env/lib/python3.6/site-packages/urllib3/connection.py", line 146, in _new_conn
    (self.host, self.timeout))
urllib3.exceptions.ConnectTimeoutError: (<urllib3.connection.VerifiedHTTPSConnection object at 0x1095d5358>, 'Connection to api.line.me timed out. (connect timeout=5)')

During handling of the above exception, another exception occurred:

Traceback (most recent call last):
  File "/Users/toshimitsu/Envs/ls-env/lib/python3.6/site-packages/requests/adapters.py", line 440, in send
    timeout=timeout
  File "/Users/toshimitsu/Envs/ls-env/lib/python3.6/site-packages/urllib3/connectionpool.py", line 639, in urlopen
    _stacktrace=sys.exc_info()[2])
  File "/Users/toshimitsu/Envs/ls-env/lib/python3.6/site-packages/urllib3/util/retry.py", line 388, in increment
    raise MaxRetryError(_pool, url, error or ResponseError(cause))
urllib3.exceptions.MaxRetryError: HTTPSConnectionPool(host='api.line.me', port=443): Max retries exceeded with url: /v2/bot/profile/Ud1ec870e773a12d3ff494a8ccf348153 (Caused by ConnectTimeoutError(<urllib3.connection.VerifiedHTTPSConnection object at 0x1095d5358>, 'Connection to api.line.me timed out. (connect timeout=5)'))

During handling of the above exception, another exception occurred:

Traceback (most recent call last):
  File "/Users/toshimitsu/Envs/ls-env/lib/python3.6/site-packages/flask/app.py", line 1982, in wsgi_app
    response = self.full_dispatch_request()
  File "/Users/toshimitsu/Envs/ls-env/lib/python3.6/site-packages/flask/app.py", line 1614, in full_dispatch_request
    rv = self.handle_user_exception(e)
  File "/Users/toshimitsu/Envs/ls-env/lib/python3.6/site-packages/flask/app.py", line 1517, in handle_user_exception
    reraise(exc_type, exc_value, tb)
  File "/Users/toshimitsu/Envs/ls-env/lib/python3.6/site-packages/flask/_compat.py", line 33, in reraise
    raise value
  File "/Users/toshimitsu/Envs/ls-env/lib/python3.6/site-packages/flask/app.py", line 1612, in full_dispatch_request
    rv = self.dispatch_request()
  File "/Users/toshimitsu/Envs/ls-env/lib/python3.6/site-packages/flask/app.py", line 1598, in dispatch_request
    return self.view_functions[rule.endpoint](**req.view_args)
  File "test_bot_lightning.py", line 96, in callback
    (event.source.user_id), group_id)
  File "/Users/toshimitsu/Envs/ls-env/lib/python3.6/site-packages/linebot/api.py", line 177, in get_profile
    timeout=timeout
  File "/Users/toshimitsu/Envs/ls-env/lib/python3.6/site-packages/linebot/api.py", line 357, in _get
    url, headers=self.headers, params=params, stream=stream, timeout=timeout
  File "/Users/toshimitsu/Envs/ls-env/lib/python3.6/site-packages/linebot/http_client.py", line 112, in get
    url, headers=headers, params=params, stream=stream, timeout=timeout
  File "/Users/toshimitsu/Envs/ls-env/lib/python3.6/site-packages/requests/api.py", line 72, in get
    return request('get', url, params=params, **kwargs)
  File "/Users/toshimitsu/Envs/ls-env/lib/python3.6/site-packages/requests/api.py", line 58, in request
    return session.request(method=method, url=url, **kwargs)
  File "/Users/toshimitsu/Envs/ls-env/lib/python3.6/site-packages/requests/sessions.py", line 508, in request
    resp = self.send(prep, **send_kwargs)
  File "/Users/toshimitsu/Envs/ls-env/lib/python3.6/site-packages/requests/sessions.py", line 618, in send
    r = adapter.send(request, **kwargs)
  File "/Users/toshimitsu/Envs/ls-env/lib/python3.6/site-packages/requests/adapters.py", line 496, in send
    raise ConnectTimeout(e, request=request)
requests.exceptions.ConnectTimeout: HTTPSConnectionPool(host='api.line.me', port=443): Max retries exceeded with url: /v2/bot/profile/Ud1ec870e773a12d3ff494a8ccf348153 (Caused by ConnectTimeoutError(<urllib3.connection.VerifiedHTTPSConnection object at 0x1095d5358>, 'Connection to api.line.me timed out. (connect timeout=5)'))
127.0.0.1 - - [29/Apr/2018 13:37:51] "POST /callback HTTP/1.1" 500 -
